#VRML_SIM R2023b utf8

EXTERNPROTO "https://raw.githubusercontent.com/cyberbotics/webots/R2023b/projects/objects/backgrounds/protos/TexturedBackground.proto"
EXTERNPROTO "https://raw.githubusercontent.com/cyberbotics/webots/R2023b/projects/objects/backgrounds/protos/TexturedBackgroundLight.proto"
EXTERNPROTO "https://raw.githubusercontent.com/cyberbotics/webots/R2023b/projects/appearances/protos/Grass.proto"
EXTERNPROTO "https://raw.githubusercontent.com/cyberbotics/webots/R2023b/projects/objects/garden/protos/DogHouse.proto"
EXTERNPROTO "https://raw.githubusercontent.com/cyberbotics/webots/R2023b/projects/objects/trees/protos/Forest.proto"
EXTERNPROTO "../protos/CypressSalient.proto"
EXTERNPROTO "../protos/RockSalient.proto"
EXTERNPROTO "https://raw.githubusercontent.com/cyberbotics/webots/R2023b/projects/objects/garden/protos/PicketFence.proto"
EXTERNPROTO "https://raw.githubusercontent.com/cyberbotics/webots/R2023b/projects/objects/animals/protos/Cow.proto"
EXTERNPROTO "https://raw.githubusercontent.com/cyberbotics/webots/R2023b/projects/objects/trees/protos/Pine.proto"
EXTERNPROTO "https://raw.githubusercontent.com/cyberbotics/webots/R2023b/projects/objects/animals/protos/Horse.proto"
EXTERNPROTO "https://raw.githubusercontent.com/cyberbotics/webots/R2023b/projects/objects/animals/protos/Sheep.proto"
EXTERNPROTO "https://raw.githubusercontent.com/cyberbotics/webots/R2023b/projects/objects/buildings/protos/Barn.proto"
EXTERNPROTO "https://raw.githubusercontent.com/cyberbotics/webots/R2023b/projects/objects/animals/protos/Fox.proto"
EXTERNPROTO "https://raw.githubusercontent.com/cyberbotics/webots/R2023b/projects/objects/garden/protos/Slide.proto"
EXTERNPROTO "https://raw.githubusercontent.com/cyberbotics/webots/R2023b/projects/objects/garden/protos/Swing.proto"
EXTERNPROTO "https://raw.githubusercontent.com/cyberbotics/webots/R2023b/projects/objects/garden/protos/Gnome.proto"
EXTERNPROTO "https://raw.githubusercontent.com/cyberbotics/webots/R2023b/projects/objects/garden/protos/SwingCouch.proto"
EXTERNPROTO "https://raw.githubusercontent.com/cyberbotics/webots/R2023b/projects/objects/obstacles/protos/OilBarrel.proto"
EXTERNPROTO "https://raw.githubusercontent.com/cyberbotics/webots/R2023b/projects/objects/buildings/protos/MotelReception.proto"
EXTERNPROTO "https://raw.githubusercontent.com/cyberbotics/webots/R2023b/projects/objects/garden/protos/Wheelbarrow.proto"
EXTERNPROTO "https://raw.githubusercontent.com/cyberbotics/webots/R2023b/projects/objects/buildings/protos/Windmill.proto"
EXTERNPROTO "https://raw.githubusercontent.com/cyberbotics/webots/R2023b/projects/objects/buildings/protos/Church.proto"
EXTERNPROTO "https://raw.githubusercontent.com/cyberbotics/webots/R2023b/projects/objects/buildings/protos/SmallManor.proto"

WorldInfo {
  contactProperties [
    ContactProperties {
      material1 "passive_wheel"
      coulombFriction [
        0
      ]
    }
  ]
}
Viewpoint {
  orientation -0.5773502691896258 0.5773502691896258 0.5773502691896258 2.0944
  position -3.8875580141312898 3.0824547477861137 34.858320509261986
}
TexturedBackground {
}
TexturedBackgroundLight {
}
DEF GROUND Solid {
  translation 0.09 0 0
  children [
    DEF GROUND_SHAPE Group {
      children [
        Pose {
          translation -15.98 -8 0
          children [
            Shape {
              appearance Grass {
                type "mossy"
                textureTransform TextureTransform {
                  scale 20 20
                }
              }
              geometry ElevationGrid {
                height [
                  0, 0, 0, 0, 0, 0, 0, 0, 0, 0, 0, 0, 0, 0, 0, 0, 0, 0, 0.00734154, 0.277421, 0.254337, 0.270417, 0.174982, 0.171189, 0.2473, 0.240992, 0.152361, 0.110575, 0.0978332, 0.126226, 0.106899, 0.0670659, 0.00953075, 0, 0, 0.499106, 0.798685, 0.613379, 0.322475, 0.287311, 0.266366, 0.418124, 0.525612, 0.0265759, 0.30729, 0.0753625, 0.0480358, 0.0532171, 0.0870809, 0.0265759, 0, 0, 0.862448, 1.07618, 0.821001, 0.384595, 0.210389, 0.0983306, 0.331182, 0.347343, 0.263181, 0.13356, 0.0145599, 0.0762221, 0.100532, 0.243507, 0.159553, 0, 0, 0.75534, 0.984221, 0.864925, 0.447235, 0.0751634, 0.0222157, 0.078995, 0.102868, 0.0300013, 0.0114454, 0.00744961, 0.00984787, 0.204083, 0.520919, 0.461261, 0, 0, 0.362822, 0.603904, 0.566029, 0.340368, 0.102151, 0.0404528, 0.0668038, 0.00744951, 0.00933689, 0.0504858, 0.00744961, -0.000948593, 0.113054, 0.320988, 0.289012, 0, 0, 0.24704, 0.327251, 0.277966, 0.170757, 0.0771545, 0.0929641, 0.00744947, 0.00744951, 0.00744954, 0.00744958, 0.00744961, 0.0223858, 0.0165338, 0.0943175, 0.0460902, 0, 0, 0.205381, 0.266736, 0.119044, 0.124862, 0.0668763, 0.106241, 0.00744947, 0.00744951, 0.00744954, 0.00744958, 0.00744961, 0.00747269, 0.0113116, 0.0207513, 0.0670393, 0, 0, 0.131618, 0.109085, 0.0721561, 0.169558, 0.124192, 0.00986459, 0.00744947, 0.00744951, 0.00744954, 0.031045, 0.0443939, 0.00800915, 0.0184385, 0.0427789, 0.204962, 0, 0, 0.283209, 0.135281, 0.068453, 0.212608, 0.159615, 0.0361041, 0.00744947, 0.00744951, 0.0121282, 0.145762, 0.2493, 0.0458433, 0.0131252, 0.131277, 0.19891, 0, 0, 0.660028, 0.539195, 0.111397, 0.132591, 0.105425, 0.0289037, 0.00744947, 0.00744951, 0.00930376, 0.162809, 0.219176, 0.0290093, 0.0131459, 0.0436956, 0.0856175, 0, 0, 0.577927, 0.513154, 0.0907302, 0.0479889, 0.0704255, 0.019278, 0.00747491, 0.00932149, 0.0307641, 0.178685, 0.171126, 0.00346421, 0.0308989, 0.0948634, 0.262075, 0, 0, 0.315194, 0.205858, 0.0314991, 0.0365704, 0.127151, 0.142281, 0.00631048, 0.0559231, 0.196945, 0.333009, 0.17502, 0.00950381, 0.0639322, 0.243806, 0.282763, 0, 0, 0.233297, 0.177544, 0.0450179, 0.0682162, 0.129357, 0.0562887, 0.0190858, 0.120147, 0.389857, 0.381918, 0.0861915, -0.000387524, 0.178523, 0.482041, 0.357671, 0, 0, 0.00946765, 0.0925988, 0.208856, 0.242312, 0.359189, 0.320955, 0.189391, 0.194184, 0.352838, 0.288278, 0.142815, 0.143518, 0.27195, 0.517513, 0.504371, 0, 0, 0.037447, 0.126832, 0.314132, 0.26641, 0.227191, 0.16272, 0.107686, 0.12869, 0.0911368, 0.130659, 0.0368771, 0.108887, 0.0914181, 0.249301, 0.291638, 0, 0, 0, 0, 0, 0, 0, 0, 0, 0, 0, 0, 0, 0, 0, 0, 0, 0
                ]
                xDimension 17
                xSpacing 1.5
                yDimension 17
                ySpacing 1.5
              }
              castShadows FALSE
            }
          ]
        }
        Shape {
          appearance Grass {
            type "mossy"
            textureTransform TextureTransform {
              scale 100 100
            }
          }
          geometry Plane {
            size 100 100
          }
        }
      ]
    }
    Pose {
      children [
        Church {
          translation -6.8737 -16.9837 0
          rotation 0 0 1 1.5708
        }
        SmallManor {
          translation -2.67345e-05 26.22 0
          rotation 0 0 1 -1.5707953071795862
        }
        Windmill {
          translation 1.58005 -9.37 0
          rotation 0 0 1 1.5708
        }
        OilBarrel {
          translation -4.72 2.21 1
          name "oil barrel(2)"
          height 2
          radius 0.5
        }
        OilBarrel {
          translation -3.47 2.17 0.99
          name "oil barrel(3)"
          height 2
          radius 0.5
        }
        Wheelbarrow {
          translation 6.92918 2.09051 0
          rotation 0 0 1 1.8326
        }
        Slide {
          translation 2.14999 13.32 0.15
          rotation 0 0 1 -1.5707953071795862
        }
        SwingCouch {
          translation -17.18 3.15 0.03
        }
        Gnome {
          translation -14.44 7.48 0.74
          rotation 0 0 1 -1.3089953071795861
        }
        Gnome {
          translation -13.9471 7.612 0.67
          rotation 0 0 -1 0.785397
          name "gnome(1)"
        }
        Gnome {
          translation -14.6681 8.45318 0.57
          rotation 0 0 1 -1.5707953071795862
          name "gnome(2)"
        }
        Swing {
          translation -4.36 12.04 0.41
          rotation 0 0 1 -1.5707953071795862
        }
        Barn {
          translation -1.81996 -4.94 0.19
          rotation 0 0 1 1.5708
          scale 0.2
        }
        OilBarrel {
          translation -8.52 -7.85 0.55
        }
        OilBarrel {
          translation -7.89 -7.84 0.55
          name "oil barrel(1)"
        }
        Barn {
          translation 10.29 -2.41998 0.19
          rotation 0 0 1 -3.1415853071795863
          scale 0.4
          name "barn(1)"
        }
        MotelReception {
          translation -20.05 9.86 0
          enableBoundingObject FALSE
        }
        DEF WALLs Group {
          children [
            Solid {
              translation -3.69 -8.28 0.470023
              rotation 2.3464099999870814e-06 -2.3464099999870814e-06 0.9999999999944944 -1.5707953071795862
              children [
                DEF INVISIBLE_WALL Shape {
                  appearance DEF TRANSPARENT PBRAppearance {
                    transparency 1
                    roughness 1
                    metalness 0
                  }
                  geometry Box {
                    size 0.02 25 0.9
                  }
                }
              ]
              name "invisible_wall"
              boundingObject USE INVISIBLE_WALL
            }
            Solid {
              translation 8.13 3.59 0.469965
              rotation -2.343280460602283e-09 0.9774071921221089 0.21136504154655075 4.80123e-06
              children [
                DEF INVISIBLE_WALL Shape {
                  appearance DEF TRANSPARENT PBRAppearance {
                    transparency 1
                    roughness 1
                    metalness 0
                  }
                  geometry Box {
                    size 0.02 25 0.9
                  }
                }
              ]
              name "invisible_wall(1)"
              boundingObject USE INVISIBLE_WALL
            }
            Solid {
              translation -4.26003 16.14 0.470023
              rotation 2.3463799999870823e-06 2.3463799999870823e-06 0.9999999999944946 1.5708
              children [
                DEF INVISIBLE_WALL Shape {
                  appearance DEF TRANSPARENT PBRAppearance {
                    transparency 1
                    roughness 1
                    metalness 0
                  }
                  geometry Box {
                    size 0.02 25 0.9
                  }
                }
              ]
              name "invisible_wall(2)"
              boundingObject USE INVISIBLE_WALL
            }
            Solid {
              translation -16.14 4.59 0.470075
              rotation 2.346379999993541e-06 5.625329999984516e-15 0.9999999999972473 -3.1415853071795863
              children [
                DEF INVISIBLE_WALL Shape {
                  appearance DEF TRANSPARENT PBRAppearance {
                    transparency 1
                    roughness 1
                    metalness 0
                  }
                  geometry Box {
                    size 0.02 25 0.9
                  }
                }
              ]
              name "invisible_wall(3)"
              boundingObject USE INVISIBLE_WALL
            }
          ]
        }
        DEF SalientTrees Group {
          children [
            CypressSalient {
              translation 2.3 7.02 0.34
              name "cypress tree scale 2.5"
              scale 1.2
            }
            Pine {
              translation -5.09 -6.1 0.16
            }
            Pine {
              translation -5.4 6.68 0.07
              name "pine tree(1)"
            }
            CypressSalient {
              translation -23.14 -12.26 0.06
              name "cypress tree scale 2.5(2)"
              scale 2.5
            }
            CypressSalient {
              translation 8.85 -6.97 1.38
              name "cypress tree scale 2.5(4)"
              scale 1.8
            }
            CypressSalient {
              translation 5.12 -5.26 0.06
              name "cypress tree scale 2.5(5)"
              scale 0.8
            }
            CypressSalient {
              translation 7.63 -9.66 0.09
              name "cypress tree scale 2.5(6)"
              scale 2.5
            }
            CypressSalient {
              translation 5 -12.2 0.06
              name "cypress tree scale 2.5(8)"
              scale 2.5
            }
            CypressSalient {
              translation 9.03 13.95 0.04
              name "cypress tree scale 2.5(10)"
              scale 1.5
            }
            CypressSalient {
              translation -12.91 -3.1 0.97
              name "cypress tree scale 2.5(25)"
              scale 0.8
            }
            CypressSalient {
              translation -15.03 15.07 0.03
              name "cypress tree scale 2.5(16)"
              scale 2.5
            }
            CypressSalient {
              translation 4.25 4.97 0.1
              name "cypress tree scale 2.5(23)"
              scale 1.4
            }
          ]
        }
        DEF SalientRocks Group {
          children [
            RockSalient {
              translation -7.00894 11.5033 0.187395
              rotation 0.3417991194664005 -0.007719942698291814 -0.9397413284605124 -2.268555307179586
              name "rock(2)"
              scale 6
            }
            RockSalient {
              translation 4.38844 9.64188 0.35
              rotation 0 0 1 1.8326
              name "rock(10)"
              type "flat"
              scale 3
            }
            RockSalient {
              translation 4.38376 -9.9748 0.06
              rotation 0 0 1 2.8798
              name "rock(4)"
              type "flat"
              scale 6
            }
            RockSalient {
              translation -11.5161 10.9894 0.17
              rotation 0 0 1 -1.047195307179586
              name "rock(11)"
              type "flat"
              scale 8
              color 0.6 0.6 0.6
            }
            RockSalient {
              translation 0.881653 -1.9041 0.524732
              rotation 0.3779641520510403 0.6546542633605892 -0.6546532633601869 1.44547
              name "rock(1)"
              scale 12
              color 0.482353 0.360784 0.360784
            }
            RockSalient {
              translation 2.6664 0.55651 0.0261
              name "rock(3)"
              type "flat"
              scale 2
              color 0.482353 0.360784 0.360784
            }
            RockSalient {
              translation -12.3736 5.82651 0.1061
              name "rock(5)"
              type "flat"
              scale 4
              color 0.756863 0.756863 0.737255
            }
          ]
        }
        DEF Structures Group {
          children [
            PicketFence {
              translation -7.53 -3.13 0.01
              numberOfSegments 3
            }
            PicketFence {
              translation -15.63 0.879996 0.25
              rotation 0 0 1 1.5708
              name "picket fence(1)"
              numberOfSegments 4
            }
          ]
        }
        Cow {
          translation -10.633 17.504 0.05
          rotation 0 0 -1 1.3089953071795861
          scale 0.5
        }
        Cow {
          translation 6.26577 18.0078 0
          rotation 0 0 1 -2.8797853071795863
          name "cow(1)"
        }
        Cow {
          translation -7.85777 17.6522 0.08
          rotation 0 0 1 -0.261795307179586
          name "cow(3)"
        }
        Cow {
          translation -11.5163 18.643 0.05
          rotation 0 0 1 0.523602
          scale 0.7
          name "cow(2)"
        }
        Cow {
          translation 4.32923 16.9218 -0.02
          rotation 0 0 -1 1.04719
          scale 0.7
          name "cow(4)"
        }
        Horse {
          translation 9.1 1.3 0.04
          rotation 0 0 1 1.5708
          colorBody 0.388235 0 0
          colorHair 0.741176 0.678431 0.682353
        }
        Horse {
          translation 0.879762 -8.73168 0.04
          rotation 0 0 1 2.87979
          scale 0.6
          name "horse(2)"
          colorBody 0.678431 0.321569 0.0666667
          colorHair 0.741176 0.678431 0.682353
        }
        Horse {
          translation 9.36935 9.653 0.04
          rotation 0 0 1 2.09439
          name "horse(3)"
          colorBody 0.972549 0.486275 0
          colorHair 0.741176 0.678431 0.682353
        }
        Horse {
          translation 9.6993 7.47068 0.04
          rotation 0 0 1 -2.094395307179586
          name "horse(4)"
          colorBody 0.972549 0.486275 0
          colorHair 0.741176 0.678431 0.682353
        }
        Horse {
          translation 9.14243 3.01883 -0.04
          rotation 0 0 1 -2.3561953071795863
          scale 0.6
          name "horse(1)"
          colorBody 0.388235 0 0
          colorHair 0.741176 0.678431 0.682353
        }
        Sheep {
          translation -16.8863 -4.96986 -0.04
          rotation 0 0 -1 -5.307179586466759e-06
          scale 0.8
        }
        Sheep {
          translation -17.1338 -1.86338 -0.04
          rotation 0 0 -1 -0.5236053071795865
          scale 1.5
          name "sheep(1)"
        }
        Sheep {
          translation -16.9874 -2.73848 -0.04
          rotation 0 0 -1 -0.5236053071795865
          name "sheep(2)"
        }
        Fox {
          translation -1.84196 17.7383 0.17
          rotation 0 0 1 -2.3561953071795863
          scale 1.5
        }
        Forest {
          translation 0.85 -21.03 0
          shape [
            -50 0
            50 0
            0 25
          ]
          density 0.1
          type "cherry tree"
          groundTexture []
        }
        Forest {
          translation 15.6 7.45 0
          rotation 0 0 1 1.5708
          shape [
            -20 0
            50 0
            0 25
          ]
          density 0.1
          type "cherry tree"
          groundTexture []
        }
        Forest {
          translation -20.4 22.07 0
          rotation 0 0 1 -3.1415853071795863
          shape [
            -20 0
            20 0
            0 25
          ]
          density 0.1
          type "cherry tree"
          groundTexture []
        }
        Forest {
          translation -33.6786 6.3224 0
          rotation 0 0 1 -1.5707953071795862
          shape [
            -20 0
            20 0
            0 25
          ]
          density 0.1
          type "cherry tree"
          groundTexture []
        }
      ]
    }
  ]
  boundingObject USE GROUND_SHAPE
  recognitionColors [
    0 0 0
  ]
}
DogHouse {
  translation -14.87 -7.38 0.11
}
DEF AGENT Robot {
  translation -0.35994 5.15998 0.22
  rotation 0 0 -1 1.5708
  children [
    TouchSensor {
      translation 0.153 0 0
      children [
        DEF TOUCHSENSOR_BODY Shape {
          geometry Box {
            size 0.005 0.2 0.05
          }
        }
      ]
      name "touchsensor_front"
      boundingObject USE TOUCHSENSOR_BODY
    }
    HingeJoint {
      jointParameters HingeJointParameters {
        axis 0 1 0
        anchor -0.1 -0.11 -0.02
      }
      device [
        RotationalMotor {
          name "wheel4"
          maxVelocity 15
        }
      ]
      endPoint DEF WHEEL4 Solid {
        translation -0.09999999999999956 -0.10999999999999943 -0.019999999999998217
        rotation 0.9999999999999999 7.576250572108984e-10 -7.576020553986238e-10 1.5707999999899473
        children [
          DEF WHEEL Shape {
            appearance PBRAppearance {
              baseColor 0 1 0
              roughness 1
              metalness 0
            }
            geometry Cylinder {
              height 0.02
              radius 0.04
            }
          }
        ]
        name "solid4(1)"
        boundingObject USE WHEEL
        physics DEF WHEEL_PH Physics {
        }
      }
    }
    HingeJoint {
      jointParameters HingeJointParameters {
        axis 0 1 0
        anchor -0.1 0.11 -0.02
      }
      device [
        RotationalMotor {
          name "wheel3"
          maxVelocity 15
        }
      ]
      endPoint DEF WHEEL3 Solid {
        translation -0.10000000000000021 0.11000000000000032 -0.019999999999999598
        rotation 0.9999999999999999 8.73791510113091e-10 -8.734871482489653e-10 1.5707999999933542
        children [
          DEF WHEEL Shape {
            appearance PBRAppearance {
              baseColor 0 1 0
              roughness 1
              metalness 0
            }
            geometry Cylinder {
              height 0.02
              radius 0.04
            }
          }
        ]
        name "solid3(1)"
        boundingObject USE WHEEL
        physics DEF WHEEL_PH Physics {
        }
      }
    }
    HingeJoint {
      jointParameters HingeJointParameters {
        axis 0 1 0
        anchor 0.1 -0.11 -0.02
      }
      device [
        RotationalMotor {
          name "wheel2"
          maxVelocity 15
        }
      ]
      endPoint DEF WHEEL2 Solid {
        translation 0.10000000000000002 -0.10999999999999943 -0.020000000000000146
        rotation 0.9999999999999999 -8.30704169940726e-11 8.303140026813234e-11 1.5707999999928555
        children [
          DEF WHEEL Shape {
            appearance PBRAppearance {
              baseColor 0 1 0
              roughness 1
              metalness 0
            }
            geometry Cylinder {
              height 0.02
              radius 0.04
            }
          }
        ]
        name "solid2(1)"
        boundingObject USE WHEEL
        physics DEF WHEEL_PH Physics {
        }
      }
    }
    HingeJoint {
      jointParameters HingeJointParameters {
        axis 0 1 0
        anchor 0.1 0.11 -0.02
      }
      device [
        RotationalMotor {
          name "wheel1"
          maxVelocity 15
        }
      ]
      endPoint DEF WHEEL1 Solid {
        translation 0.09999999999999956 0.11000000000000032 -0.019999999999998925
        rotation 0.9999999999999999 -5.33375836085315e-10 5.33815775184248e-10 1.57079999998963
        children [
          DEF WHEEL Shape {
            appearance PBRAppearance {
              baseColor 0 1 0
              roughness 1
              metalness 0
            }
            geometry Cylinder {
              height 0.02
              radius 0.04
            }
          }
        ]
        name "solid(1)"
        boundingObject USE WHEEL
        physics DEF WHEEL_PH Physics {
        }
      }
    }
    Solid {
      translation 5.15213e-15 1.74204e-21 1.55
      rotation 0 0 1 1.01503e-06
      children [
        Display {
          width 10
          height 10
        }
        Camera {
          fieldOfView 2.356
          width 256
          height 256
          recognition Recognition {
            segmentation TRUE
          }
        }
        DEF CAMERA_SHAPE Shape {
          appearance PBRAppearance {
          }
          geometry Box {
            size 0.02 0.02 0.02
          }
        }
      ]
      name "camera_box"
      boundingObject USE CAMERA_SHAPE
    }
    DEF ROBOT Group {
      children [
        Pose {
          translation 0 0 0.75
          children [
            Shape {
              appearance PBRAppearance {
              }
              geometry Box {
                size 0.02 0.02 1.5
              }
            }
          ]
        }
        Shape {
          appearance PBRAppearance {
          }
          geometry Box {
            size 0.3 0.2 0.05
          }
        }
      ]
    }
    DistanceSensor {
      translation 0.13634 0.045 0.03
      rotation 0 0 1 0.523599
      children [
        DEF DS_SHAPE Shape {
          appearance PBRAppearance {
          }
          geometry Box {
            size 0.01 0.01 0.01
          }
        }
      ]
      name "ds1"
      boundingObject USE DS_SHAPE
      lookupTable [
        0 0 0
        0.5 100 0
      ]
      aperture 2
    }
    DistanceSensor {
      translation 0.135 0 0.03
      children [
        DEF DS_SHAPE Shape {
          appearance PBRAppearance {
          }
          geometry Box {
            size 0.01 0.01 0.01
          }
        }
      ]
      name "ds2"
      boundingObject USE DS_SHAPE
      lookupTable [
        0 0 0
        0.5 100 0
      ]
      aperture 2
    }
    DistanceSensor {
      translation 0.13634 -0.045 0.03
      rotation 0 0 1 -0.523595307179586
      children [
        DEF DS_SHAPE Shape {
          appearance PBRAppearance {
          }
          geometry Box {
            size 0.01 0.01 0.01
          }
        }
      ]
      name "ds3"
      boundingObject USE DS_SHAPE
      lookupTable [
        0 0 0
        0.5 100 0
      ]
      aperture 2
    }
    DistanceSensor {
      translation 0.07 -0.09 0.03
      rotation 0 0 1 -0.785395307179586
      children [
        DEF DS_SHAPE Shape {
          appearance PBRAppearance {
          }
          geometry Box {
            size 0.01 0.01 0.01
          }
        }
      ]
      name "ds4"
      boundingObject USE DS_SHAPE
      lookupTable [
        0 0 0
        0.5 100 0
      ]
      aperture 2
    }
    DistanceSensor {
      translation 0 -0.09 0.03
      rotation 0 0 1 -1.5707953071795862
      children [
        DEF DS_SHAPE Shape {
          appearance PBRAppearance {
          }
          geometry Box {
            size 0.01 0.01 0.01
          }
        }
      ]
      name "ds5"
      boundingObject USE DS_SHAPE
      lookupTable [
        0 0 0
        0.5 100 0
      ]
      aperture 2
    }
    DistanceSensor {
      translation -0.07 -0.09 0.03
      rotation 0 0 1 -2.094395307179586
      children [
        DEF DS_SHAPE Shape {
          appearance PBRAppearance {
          }
          geometry Box {
            size 0.01 0.01 0.01
          }
        }
      ]
      name "ds6"
      boundingObject USE DS_SHAPE
      lookupTable [
        0 0 0
        0.5 100 0
      ]
      aperture 2
    }
    DistanceSensor {
      translation -0.14 -0.05 0.03
      rotation 0 0 -1 2.618
      children [
        DEF DS_SHAPE Shape {
          appearance PBRAppearance {
          }
          geometry Box {
            size 0.01 0.01 0.01
          }
        }
      ]
      name "ds7"
      boundingObject USE DS_SHAPE
      lookupTable [
        0 0 0
        0.5 100 0
      ]
      aperture 2
    }
    DistanceSensor {
      translation -0.14 0 0.03
      rotation 0 0 1 3.14159
      children [
        DEF DS_SHAPE Shape {
          appearance PBRAppearance {
          }
          geometry Box {
            size 0.01 0.01 0.01
          }
        }
      ]
      name "ds8"
      boundingObject USE DS_SHAPE
      lookupTable [
        0 0 0
        0.5 100 0
      ]
      aperture 2
    }
    DistanceSensor {
      translation -0.14 0.05 0.03
      rotation 0 0 1 2.61799
      children [
        DEF DS_SHAPE Shape {
          appearance PBRAppearance {
          }
          geometry Box {
            size 0.01 0.01 0.01
          }
        }
      ]
      name "ds9"
      boundingObject USE DS_SHAPE
      lookupTable [
        0 0 0
        0.5 100 0
      ]
      aperture 2
    }
    DistanceSensor {
      translation -0.07 0.09 0.03
      rotation 0 0 1 2.0944
      children [
        DEF DS_SHAPE Shape {
          appearance PBRAppearance {
          }
          geometry Box {
            size 0.01 0.01 0.01
          }
        }
      ]
      name "ds10"
      boundingObject USE DS_SHAPE
      lookupTable [
        0 0 0
        0.5 100 0
      ]
      aperture 2
    }
    DistanceSensor {
      translation 0 0.09 0.03
      rotation 0 0 1 1.5708
      children [
        DEF DS_SHAPE Shape {
          appearance PBRAppearance {
          }
          geometry Box {
            size 0.01 0.01 0.01
          }
        }
      ]
      name "ds11"
      boundingObject USE DS_SHAPE
      lookupTable [
        0 0 0
        0.5 100 0
      ]
      aperture 2
    }
    DistanceSensor {
      translation 0.07 0.09 0.03
      rotation 0 0 1 0.785398
      children [
        DEF DS_SHAPE Shape {
          appearance PBRAppearance {
          }
          geometry Box {
            size 0.01 0.01 0.01
          }
        }
      ]
      name "ds12"
      boundingObject USE DS_SHAPE
      lookupTable [
        0 0 0
        0.5 100 0
      ]
      aperture 2
    }
  ]
  boundingObject USE ROBOT
  physics Physics {
  }
  controller "<extern>"
  supervisor TRUE
}
